2018-11-12T16:33:26|CRITICAL|root|Unhandled exception:Traceback (most recent call last):
  File "C:\ProgramData\Anaconda3\lib\site-packages\ScopeFoundry\hardware.py", line 208, in enable_connection
    raise err
  File "C:\ProgramData\Anaconda3\lib\site-packages\ScopeFoundry\hardware.py", line 204, in enable_connection
    self.connect()
  File "C:\Users\Admin\Desktop\Camera-ScopeFoundry\CameraHardware.py", line 32, in connect
    self.hamamatsu = HamamatsuDeviceMR(camera_id=0, frame_x=self.subarrayh.val, frame_y=self.subarrayv.val, acquisition_mode=self.acquisition_mode.val, number_frames=self.number_frames.val, exposure=self.exposure_time.val, trsource=self.trsource.val, trmode=self.trmode.val, trpolarity=self.trpolarity.val ) #maybe with more cameras we have to change
  File "C:\Users\Admin\Desktop\Camera-ScopeFoundry\CameraDevice.py", line 859, in __init__
    super().__init__(**kwds)
  File "C:\Users\Admin\Desktop\Camera-ScopeFoundry\CameraDevice.py", line 309, in __init__
    self.setTriggerSource(self.trig_dict_source[trsource])
  File "C:\Users\Admin\Desktop\Camera-ScopeFoundry\CameraDevice.py", line 760, in setTriggerSource
    self.setPropertyValue("trigger_source", self.trig_dict_source[trsource])
KeyError: 2

