2018-11-15T16:09:56|CRITICAL|root|Unhandled exception:Traceback (most recent call last):
  File "C:\ProgramData\Anaconda3\lib\site-packages\ScopeFoundry\hardware.py", line 208, in enable_connection
    raise err
  File "C:\ProgramData\Anaconda3\lib\site-packages\ScopeFoundry\hardware.py", line 204, in enable_connection
    self.connect()
  File "C:\Users\Admin\Desktop\Camera-ScopeFoundry\CameraHardware.py", line 56, in connect
    self.hamamatsu = HamamatsuDeviceMR(camera_id=0, frame_x=self.subarrayh.val, frame_y=self.subarrayv.val, acquisition_mode=self.acquisition_mode.val, number_frames=self.number_frames.val, exposure=self.exposure_time.val, trsource=self.trsource.val, trmode=self.trmode.val, trpolarity=self.trpolarity.val ) #maybe with more cameras we have to change
  File "C:\Users\Admin\Desktop\Camera-ScopeFoundry\CameraDevice.py", line 904, in __init__
    super().__init__(**kwds)
  File "C:\Users\Admin\Desktop\Camera-ScopeFoundry\CameraDevice.py", line 326, in __init__
    self.setExposure(exposure)
  File "C:\Users\Admin\Desktop\Camera-ScopeFoundry\CameraDevice.py", line 689, in setExposure
    self.setPropertyValue("exposure_time", exposure)
  File "C:\Users\Admin\Desktop\Camera-ScopeFoundry\CameraDevice.py", line 749, in setPropertyValue
    if param == DCAMERR_INVALIDPARAM:
NameError: name 'DCAMERR_INVALIDPARAM' is not defined

