2018-11-12T17:08:43|CRITICAL|root|Unhandled exception:Traceback (most recent call last):
  File "C:\Users\Admin\Desktop\Camera-ScopeFoundry\CameraMeasurement.py", line 64, in run
    self.camera.hamamatsu.startAcquisition()
AttributeError: 'HamamatsuHardware' object has no attribute 'hamamatsu'

During handling of the above exception, another exception occurred:

Traceback (most recent call last):
  File "C:\ProgramData\Anaconda3\lib\site-packages\ScopeFoundry\measurement.py", line 25, in run
    self.measurement._thread_run()
  File "C:\ProgramData\Anaconda3\lib\site-packages\ScopeFoundry\measurement.py", line 179, in _thread_run
    self.run()
  File "C:\Users\Admin\Desktop\Camera-ScopeFoundry\CameraMeasurement.py", line 99, in run
    self.camera.hamamatsu.stopAcquisition()
AttributeError: 'HamamatsuHardware' object has no attribute 'hamamatsu'

2018-11-12T17:08:46|CRITICAL|root|Unhandled exception:Traceback (most recent call last):
  File "C:\Users\Admin\Desktop\Camera-ScopeFoundry\CameraMeasurement.py", line 64, in run
    self.camera.hamamatsu.startAcquisition()
AttributeError: 'HamamatsuHardware' object has no attribute 'hamamatsu'

During handling of the above exception, another exception occurred:

Traceback (most recent call last):
  File "C:\ProgramData\Anaconda3\lib\site-packages\ScopeFoundry\measurement.py", line 25, in run
    self.measurement._thread_run()
  File "C:\ProgramData\Anaconda3\lib\site-packages\ScopeFoundry\measurement.py", line 179, in _thread_run
    self.run()
  File "C:\Users\Admin\Desktop\Camera-ScopeFoundry\CameraMeasurement.py", line 99, in run
    self.camera.hamamatsu.stopAcquisition()
AttributeError: 'HamamatsuHardware' object has no attribute 'hamamatsu'

2018-11-12T17:08:48|CRITICAL|root|Unhandled exception:Traceback (most recent call last):
  File "C:\Users\Admin\Desktop\Camera-ScopeFoundry\CameraMeasurement.py", line 64, in run
    self.camera.hamamatsu.startAcquisition()
AttributeError: 'HamamatsuHardware' object has no attribute 'hamamatsu'

During handling of the above exception, another exception occurred:

Traceback (most recent call last):
  File "C:\ProgramData\Anaconda3\lib\site-packages\ScopeFoundry\measurement.py", line 25, in run
    self.measurement._thread_run()
  File "C:\ProgramData\Anaconda3\lib\site-packages\ScopeFoundry\measurement.py", line 179, in _thread_run
    self.run()
  File "C:\Users\Admin\Desktop\Camera-ScopeFoundry\CameraMeasurement.py", line 99, in run
    self.camera.hamamatsu.stopAcquisition()
AttributeError: 'HamamatsuHardware' object has no attribute 'hamamatsu'

