2018-11-09T15:30:46|CRITICAL|root|Unhandled exception:Traceback (most recent call last):
  File "C:\ProgramData\Anaconda3\lib\site-packages\ScopeFoundry\hardware.py", line 208, in enable_connection
    raise err
  File "C:\ProgramData\Anaconda3\lib\site-packages\ScopeFoundry\hardware.py", line 204, in enable_connection
    self.connect()
  File "C:\Users\Admin\Desktop\Camera-ScopeFoundry\CameraHardware.py", line 30, in connect
    self.hamamatsu = HamamatsuDevice(camera_id=0, frame_x=self.subarrayh.val, frame_y=self.subarrayv.val, acquisition_mode=self.acquisition_mode.val, number_frames=self.number_frames.val, exposure=self.exposure_time.val ) #maybe with more cameras we have to change
  File "C:\Users\Admin\Desktop\Camera-ScopeFoundry\CameraDevice.py", line 271, in __init__
    self.exposure_time = self.setExposure(exposure)
  File "C:\Users\Admin\Desktop\Camera-ScopeFoundry\CameraDevice.py", line 653, in setExposure
    self.setPropertyValue("exposure_time", exposure)
  File "C:\Users\Admin\Desktop\Camera-ScopeFoundry\CameraDevice.py", line 669, in setPropertyValue
    if not (property_name in self.properties):
TypeError: argument of type 'NoneType' is not iterable

