2018-11-28T17:28:40|CRITICAL|root|Unhandled exception:Traceback (most recent call last):
  File "C:\ProgramData\Anaconda3\lib\site-packages\ScopeFoundry\measurement.py", line 25, in run
    self.measurement._thread_run()
  File "C:\ProgramData\Anaconda3\lib\site-packages\ScopeFoundry\measurement.py", line 179, in _thread_run
    self.run()
  File "C:\LabPrograms\Python\Camera-ScopeFoundry\CameraMeasurement.py", line 140, in run
    self.image = np.reshape(self.np_data,(self.eff_subarrayv, self.eff_subarrayh))
  File "C:\ProgramData\Anaconda3\lib\site-packages\numpy\core\fromnumeric.py", line 279, in reshape
    return _wrapfunc(a, 'reshape', newshape, order=order)
  File "C:\ProgramData\Anaconda3\lib\site-packages\numpy\core\fromnumeric.py", line 51, in _wrapfunc
    return getattr(obj, method)(*args, **kwds)
ValueError: cannot reshape array of size 0 into shape (2048,2048)

