2018-11-26T16:20:29|CRITICAL|root|Unhandled exception:Traceback (most recent call last):
  File "C:\ProgramData\Anaconda3\lib\site-packages\pyqtgraph\graphicsItems\HistogramLUTItem.py", line 195, in imageChanged
    h = self.imageItem().getHistogram()
  File "C:\ProgramData\Anaconda3\lib\site-packages\pyqtgraph\graphicsItems\ImageItem.py", line 464, in getHistogram
    bins = np.arange(mn, mx+1.01*step, step, dtype=np.int)
ValueError: arange: cannot compute length

2018-11-26T16:20:29|CRITICAL|root|Unhandled exception:Traceback (most recent call last):
  File "C:\ProgramData\Anaconda3\lib\site-packages\pyqtgraph\graphicsItems\HistogramLUTItem.py", line 195, in imageChanged
    h = self.imageItem().getHistogram()
  File "C:\ProgramData\Anaconda3\lib\site-packages\pyqtgraph\graphicsItems\ImageItem.py", line 464, in getHistogram
    bins = np.arange(mn, mx+1.01*step, step, dtype=np.int)
ValueError: arange: cannot compute length

2018-11-26T16:20:30|CRITICAL|root|Unhandled exception:Traceback (most recent call last):
  File "C:\ProgramData\Anaconda3\lib\site-packages\pyqtgraph\graphicsItems\HistogramLUTItem.py", line 195, in imageChanged
    h = self.imageItem().getHistogram()
  File "C:\ProgramData\Anaconda3\lib\site-packages\pyqtgraph\graphicsItems\ImageItem.py", line 464, in getHistogram
    bins = np.arange(mn, mx+1.01*step, step, dtype=np.int)
ValueError: arange: cannot compute length

2018-11-26T16:20:30|CRITICAL|root|Unhandled exception:Traceback (most recent call last):
  File "C:\ProgramData\Anaconda3\lib\site-packages\pyqtgraph\graphicsItems\HistogramLUTItem.py", line 195, in imageChanged
    h = self.imageItem().getHistogram()
  File "C:\ProgramData\Anaconda3\lib\site-packages\pyqtgraph\graphicsItems\ImageItem.py", line 464, in getHistogram
    bins = np.arange(mn, mx+1.01*step, step, dtype=np.int)
ValueError: arange: cannot compute length

2018-11-26T16:20:30|CRITICAL|root|Unhandled exception:Traceback (most recent call last):
  File "C:\ProgramData\Anaconda3\lib\site-packages\pyqtgraph\graphicsItems\HistogramLUTItem.py", line 195, in imageChanged
    h = self.imageItem().getHistogram()
  File "C:\ProgramData\Anaconda3\lib\site-packages\pyqtgraph\graphicsItems\ImageItem.py", line 464, in getHistogram
    bins = np.arange(mn, mx+1.01*step, step, dtype=np.int)
ValueError: arange: cannot compute length

2018-11-26T16:20:30|CRITICAL|root|Unhandled exception:Traceback (most recent call last):
  File "C:\ProgramData\Anaconda3\lib\site-packages\pyqtgraph\graphicsItems\HistogramLUTItem.py", line 195, in imageChanged
    h = self.imageItem().getHistogram()
  File "C:\ProgramData\Anaconda3\lib\site-packages\pyqtgraph\graphicsItems\ImageItem.py", line 464, in getHistogram
    bins = np.arange(mn, mx+1.01*step, step, dtype=np.int)
ValueError: arange: cannot compute length

2018-11-26T16:20:30|CRITICAL|root|Unhandled exception:Traceback (most recent call last):
  File "C:\ProgramData\Anaconda3\lib\site-packages\pyqtgraph\graphicsItems\HistogramLUTItem.py", line 195, in imageChanged
    h = self.imageItem().getHistogram()
  File "C:\ProgramData\Anaconda3\lib\site-packages\pyqtgraph\graphicsItems\ImageItem.py", line 464, in getHistogram
    bins = np.arange(mn, mx+1.01*step, step, dtype=np.int)
ValueError: arange: cannot compute length

2018-11-26T16:20:31|CRITICAL|root|Unhandled exception:Traceback (most recent call last):
  File "C:\ProgramData\Anaconda3\lib\site-packages\pyqtgraph\graphicsItems\HistogramLUTItem.py", line 195, in imageChanged
    h = self.imageItem().getHistogram()
  File "C:\ProgramData\Anaconda3\lib\site-packages\pyqtgraph\graphicsItems\ImageItem.py", line 464, in getHistogram
    bins = np.arange(mn, mx+1.01*step, step, dtype=np.int)
ValueError: arange: cannot compute length

2018-11-26T16:20:31|CRITICAL|root|Unhandled exception:Traceback (most recent call last):
  File "C:\ProgramData\Anaconda3\lib\site-packages\pyqtgraph\graphicsItems\HistogramLUTItem.py", line 195, in imageChanged
    h = self.imageItem().getHistogram()
  File "C:\ProgramData\Anaconda3\lib\site-packages\pyqtgraph\graphicsItems\ImageItem.py", line 464, in getHistogram
    bins = np.arange(mn, mx+1.01*step, step, dtype=np.int)
ValueError: arange: cannot compute length

2018-11-26T16:20:33|CRITICAL|root|Unhandled exception:Traceback (most recent call last):
  File "C:\LabPrograms\Python\Camera-ScopeFoundry\CameraMeasurement.py", line 161, in run
    if not self.h5file:
AttributeError: 'HamamatsuMeasurement' object has no attribute 'h5file'

During handling of the above exception, another exception occurred:

Traceback (most recent call last):
  File "C:\ProgramData\Anaconda3\lib\site-packages\ScopeFoundry\measurement.py", line 25, in run
    self.measurement._thread_run()
  File "C:\ProgramData\Anaconda3\lib\site-packages\ScopeFoundry\measurement.py", line 179, in _thread_run
    self.run()
  File "C:\LabPrograms\Python\Camera-ScopeFoundry\CameraMeasurement.py", line 259, in run
    self.h5file.close() # close connection
AttributeError: 'HamamatsuMeasurement' object has no attribute 'h5file'

2018-11-26T16:20:50|CRITICAL|root|Unhandled exception:Traceback (most recent call last):
  File "C:\ProgramData\Anaconda3\lib\site-packages\pyqtgraph\graphicsItems\HistogramLUTItem.py", line 195, in imageChanged
    h = self.imageItem().getHistogram()
  File "C:\ProgramData\Anaconda3\lib\site-packages\pyqtgraph\graphicsItems\ImageItem.py", line 464, in getHistogram
    bins = np.arange(mn, mx+1.01*step, step, dtype=np.int)
ValueError: arange: cannot compute length

2018-11-26T16:20:50|CRITICAL|root|Unhandled exception:Traceback (most recent call last):
  File "C:\ProgramData\Anaconda3\lib\site-packages\pyqtgraph\graphicsItems\HistogramLUTItem.py", line 195, in imageChanged
    h = self.imageItem().getHistogram()
  File "C:\ProgramData\Anaconda3\lib\site-packages\pyqtgraph\graphicsItems\ImageItem.py", line 464, in getHistogram
    bins = np.arange(mn, mx+1.01*step, step, dtype=np.int)
ValueError: arange: cannot compute length

2018-11-26T16:20:50|CRITICAL|root|Unhandled exception:Traceback (most recent call last):
  File "C:\ProgramData\Anaconda3\lib\site-packages\pyqtgraph\graphicsItems\HistogramLUTItem.py", line 195, in imageChanged
    h = self.imageItem().getHistogram()
  File "C:\ProgramData\Anaconda3\lib\site-packages\pyqtgraph\graphicsItems\ImageItem.py", line 464, in getHistogram
    bins = np.arange(mn, mx+1.01*step, step, dtype=np.int)
ValueError: arange: cannot compute length

2018-11-26T16:20:50|CRITICAL|root|Unhandled exception:Traceback (most recent call last):
  File "C:\ProgramData\Anaconda3\lib\site-packages\pyqtgraph\graphicsItems\HistogramLUTItem.py", line 195, in imageChanged
    h = self.imageItem().getHistogram()
  File "C:\ProgramData\Anaconda3\lib\site-packages\pyqtgraph\graphicsItems\ImageItem.py", line 464, in getHistogram
    bins = np.arange(mn, mx+1.01*step, step, dtype=np.int)
ValueError: arange: cannot compute length

2018-11-26T16:20:50|CRITICAL|root|Unhandled exception:Traceback (most recent call last):
  File "C:\ProgramData\Anaconda3\lib\site-packages\pyqtgraph\graphicsItems\HistogramLUTItem.py", line 195, in imageChanged
    h = self.imageItem().getHistogram()
  File "C:\ProgramData\Anaconda3\lib\site-packages\pyqtgraph\graphicsItems\ImageItem.py", line 464, in getHistogram
    bins = np.arange(mn, mx+1.01*step, step, dtype=np.int)
ValueError: arange: cannot compute length

2018-11-26T16:20:50|CRITICAL|root|Unhandled exception:Traceback (most recent call last):
  File "C:\ProgramData\Anaconda3\lib\site-packages\pyqtgraph\graphicsItems\HistogramLUTItem.py", line 195, in imageChanged
    h = self.imageItem().getHistogram()
  File "C:\ProgramData\Anaconda3\lib\site-packages\pyqtgraph\graphicsItems\ImageItem.py", line 464, in getHistogram
    bins = np.arange(mn, mx+1.01*step, step, dtype=np.int)
ValueError: arange: cannot compute length

2018-11-26T16:20:51|CRITICAL|root|Unhandled exception:Traceback (most recent call last):
  File "C:\LabPrograms\Python\Camera-ScopeFoundry\CameraMeasurement.py", line 161, in run
    if not self.h5file:
AttributeError: 'HamamatsuMeasurement' object has no attribute 'h5file'

During handling of the above exception, another exception occurred:

Traceback (most recent call last):
  File "C:\ProgramData\Anaconda3\lib\site-packages\ScopeFoundry\measurement.py", line 25, in run
    self.measurement._thread_run()
  File "C:\ProgramData\Anaconda3\lib\site-packages\ScopeFoundry\measurement.py", line 179, in _thread_run
    self.run()
  File "C:\LabPrograms\Python\Camera-ScopeFoundry\CameraMeasurement.py", line 259, in run
    self.h5file.close() # close connection
AttributeError: 'HamamatsuMeasurement' object has no attribute 'h5file'

2018-11-26T16:21:03|CRITICAL|root|Unhandled exception:Traceback (most recent call last):
  File "C:\ProgramData\Anaconda3\lib\site-packages\pyqtgraph\graphicsItems\HistogramLUTItem.py", line 195, in imageChanged
    h = self.imageItem().getHistogram()
  File "C:\ProgramData\Anaconda3\lib\site-packages\pyqtgraph\graphicsItems\ImageItem.py", line 464, in getHistogram
    bins = np.arange(mn, mx+1.01*step, step, dtype=np.int)
ValueError: arange: cannot compute length

2018-11-26T16:21:03|CRITICAL|root|Unhandled exception:Traceback (most recent call last):
  File "C:\ProgramData\Anaconda3\lib\site-packages\pyqtgraph\graphicsItems\HistogramLUTItem.py", line 195, in imageChanged
    h = self.imageItem().getHistogram()
  File "C:\ProgramData\Anaconda3\lib\site-packages\pyqtgraph\graphicsItems\ImageItem.py", line 464, in getHistogram
    bins = np.arange(mn, mx+1.01*step, step, dtype=np.int)
ValueError: arange: cannot compute length

2018-11-26T16:21:03|CRITICAL|root|Unhandled exception:Traceback (most recent call last):
  File "C:\ProgramData\Anaconda3\lib\site-packages\pyqtgraph\graphicsItems\HistogramLUTItem.py", line 195, in imageChanged
    h = self.imageItem().getHistogram()
  File "C:\ProgramData\Anaconda3\lib\site-packages\pyqtgraph\graphicsItems\ImageItem.py", line 464, in getHistogram
    bins = np.arange(mn, mx+1.01*step, step, dtype=np.int)
ValueError: arange: cannot compute length

2018-11-26T16:21:03|CRITICAL|root|Unhandled exception:Traceback (most recent call last):
  File "C:\ProgramData\Anaconda3\lib\site-packages\pyqtgraph\graphicsItems\HistogramLUTItem.py", line 195, in imageChanged
    h = self.imageItem().getHistogram()
  File "C:\ProgramData\Anaconda3\lib\site-packages\pyqtgraph\graphicsItems\ImageItem.py", line 464, in getHistogram
    bins = np.arange(mn, mx+1.01*step, step, dtype=np.int)
ValueError: arange: cannot compute length

2018-11-26T16:21:04|CRITICAL|root|Unhandled exception:Traceback (most recent call last):
  File "C:\ProgramData\Anaconda3\lib\site-packages\pyqtgraph\graphicsItems\HistogramLUTItem.py", line 195, in imageChanged
    h = self.imageItem().getHistogram()
  File "C:\ProgramData\Anaconda3\lib\site-packages\pyqtgraph\graphicsItems\ImageItem.py", line 464, in getHistogram
    bins = np.arange(mn, mx+1.01*step, step, dtype=np.int)
ValueError: arange: cannot compute length

2018-11-26T16:21:04|CRITICAL|root|Unhandled exception:Traceback (most recent call last):
  File "C:\ProgramData\Anaconda3\lib\site-packages\pyqtgraph\graphicsItems\HistogramLUTItem.py", line 195, in imageChanged
    h = self.imageItem().getHistogram()
  File "C:\ProgramData\Anaconda3\lib\site-packages\pyqtgraph\graphicsItems\ImageItem.py", line 464, in getHistogram
    bins = np.arange(mn, mx+1.01*step, step, dtype=np.int)
ValueError: arange: cannot compute length

2018-11-26T16:21:04|CRITICAL|root|Unhandled exception:Traceback (most recent call last):
  File "C:\LabPrograms\Python\Camera-ScopeFoundry\CameraMeasurement.py", line 161, in run
    if not self.h5file:
AttributeError: 'HamamatsuMeasurement' object has no attribute 'h5file'

During handling of the above exception, another exception occurred:

Traceback (most recent call last):
  File "C:\ProgramData\Anaconda3\lib\site-packages\ScopeFoundry\measurement.py", line 25, in run
    self.measurement._thread_run()
  File "C:\ProgramData\Anaconda3\lib\site-packages\ScopeFoundry\measurement.py", line 179, in _thread_run
    self.run()
  File "C:\LabPrograms\Python\Camera-ScopeFoundry\CameraMeasurement.py", line 259, in run
    self.h5file.close() # close connection
AttributeError: 'HamamatsuMeasurement' object has no attribute 'h5file'

