2018-11-26T18:47:36|CRITICAL|root|Unhandled exception:Traceback (most recent call last):
  File "C:\ProgramData\Anaconda3\lib\site-packages\pyqtgraph\graphicsItems\HistogramLUTItem.py", line 195, in imageChanged
    h = self.imageItem().getHistogram()
  File "C:\ProgramData\Anaconda3\lib\site-packages\pyqtgraph\graphicsItems\ImageItem.py", line 464, in getHistogram
    bins = np.arange(mn, mx+1.01*step, step, dtype=np.int)
ValueError: arange: cannot compute length

2018-11-26T18:47:49|CRITICAL|root|Unhandled exception:Traceback (most recent call last):
  File "C:\ProgramData\Anaconda3\lib\site-packages\ScopeFoundry\measurement.py", line 25, in run
    self.measurement._thread_run()
  File "C:\ProgramData\Anaconda3\lib\site-packages\ScopeFoundry\measurement.py", line 179, in _thread_run
    self.run()
  File "C:\LabPrograms\Python\Camera-ScopeFoundry\CameraMeasurement.py", line 91, in run
    self.camera.read_from_hardware()
  File "C:\ProgramData\Anaconda3\lib\site-packages\ScopeFoundry\hardware.py", line 181, in read_from_hardware
    lq.read_from_hardware()
  File "C:\ProgramData\Anaconda3\lib\site-packages\ScopeFoundry\logged_quantity.py", line 161, in read_from_hardware
    val = self.hardware_read_func()
  File "C:\LabPrograms\Python\Camera-ScopeFoundry\CameraDevice.py", line 1060, in getTriggerSource
    return inv_dict[self.getPropertyValue("trigger_source")[0]]
KeyError: False

