2018-11-28T15:09:31|CRITICAL|root|Unhandled exception:Traceback (most recent call last):
  File "C:\ProgramData\Anaconda3\lib\site-packages\ScopeFoundry\measurement.py", line 25, in run
    self.measurement._thread_run()
  File "C:\ProgramData\Anaconda3\lib\site-packages\ScopeFoundry\measurement.py", line 179, in _thread_run
    self.run()
  File "C:\LabPrograms\Python\Camera-ScopeFoundry\CameraMeasurement.py", line 146, in run
    self.initH5()
  File "C:\LabPrograms\Python\Camera-ScopeFoundry\CameraMeasurement.py", line 253, in initH5
    dtype = self.image.dtype, chunks = True
TypeError: create_dataset() got multiple values for argument 'name'

