2018-11-08T11:58:23|CRITICAL|root|Unhandled exception:Traceback (most recent call last):
  File "C:\ProgramData\Anaconda3\lib\site-packages\ScopeFoundry\hardware.py", line 208, in enable_connection
    raise err
  File "C:\ProgramData\Anaconda3\lib\site-packages\ScopeFoundry\hardware.py", line 204, in enable_connection
    self.connect()
  File "C:\Users\Admin\Desktop\Camera-ScopeFoundry\CameraHardware.py", line 17, in connect
    self.hamamatsu = HamamatsuDevice()
  File "C:\Users\Admin\Desktop\Camera-ScopeFoundry\CameraDevice.py", line 276, in __init__
    self.camera_model = self.getModelInfo(camera_id)
TypeError: getModelInfo() takes 1 positional argument but 2 were given

