2018-11-09T10:19:46|CRITICAL|root|Unhandled exception:Traceback (most recent call last):
  File "C:\ProgramData\Anaconda3\lib\site-packages\ScopeFoundry\hardware.py", line 208, in enable_connection
    raise err
  File "C:\ProgramData\Anaconda3\lib\site-packages\ScopeFoundry\hardware.py", line 204, in enable_connection
    self.connect()
  File "C:\Users\Admin\Desktop\Camera-ScopeFoundry\CameraHardware.py", line 42, in connect
    self.set_from_hardware()
AttributeError: 'HamamatsuHardware' object has no attribute 'set_from_hardware'

