2018-11-09T15:13:00|CRITICAL|root|Unhandled exception:Traceback (most recent call last):
  File "C:\ProgramData\Anaconda3\lib\site-packages\ScopeFoundry\hardware.py", line 208, in enable_connection
    raise err
  File "C:\ProgramData\Anaconda3\lib\site-packages\ScopeFoundry\hardware.py", line 204, in enable_connection
    self.connect()
  File "C:\Users\Admin\Desktop\Camera-ScopeFoundry\CameraHardware.py", line 30, in connect
    self.hamamatsu = HamamatsuDevice(camera_id=0, frame_x=self.subarrayh.val, frame_y=self.subarrayv.val, acquisition_mode=self.acquisition_mode.val, number_frames=self.number_frames.val, exposure=self.exposure_time.val ) #maybe with more cameras we have to change
  File "C:\Users\Admin\Desktop\Camera-ScopeFoundry\CameraDevice.py", line 271, in __init__
    self.exposure = setExposure(exposure)
NameError: name 'setExposure' is not defined

2018-11-09T15:13:01|CRITICAL|root|Unhandled exception:Traceback (most recent call last):
  File "C:\Users\Admin\Desktop\Camera-ScopeFoundry\CameraMeasurement.py", line 64, in run
    self.camera.hamamatsu.startAcquisition()
AttributeError: 'HamamatsuHardware' object has no attribute 'hamamatsu'

During handling of the above exception, another exception occurred:

Traceback (most recent call last):
  File "C:\ProgramData\Anaconda3\lib\site-packages\ScopeFoundry\measurement.py", line 25, in run
    self.measurement._thread_run()
  File "C:\ProgramData\Anaconda3\lib\site-packages\ScopeFoundry\measurement.py", line 179, in _thread_run
    self.run()
  File "C:\Users\Admin\Desktop\Camera-ScopeFoundry\CameraMeasurement.py", line 84, in run
    self.camera.hamamatsu.stopAcquisition()
AttributeError: 'HamamatsuHardware' object has no attribute 'hamamatsu'

