2018-11-30T11:33:22|CRITICAL|root|Unhandled exception:Traceback (most recent call last):
  File "C:\LabPrograms\Python\Camera-ScopeFoundry\CameraApp.py", line 51, in <module>
    app = HamamatsuApp(sys.argv)
  File "C:\LabPrograms\Python\Camera-ScopeFoundry\CameraApp.py", line 18, in __init__
    super().__init__(*kwds) # *kwds is needed since in the main we pass as argument sys.argv. Without
  File "C:\ProgramData\Anaconda3\lib\site-packages\ScopeFoundry\base_app.py", line 332, in __init__
    self.setup()
  File "C:\LabPrograms\Python\Camera-ScopeFoundry\CameraApp.py", line 32, in setup
    self.add_measurement(HamamatsuMeasurement(self))
  File "C:\ProgramData\Anaconda3\lib\site-packages\ScopeFoundry\measurement.py", line 93, in __init__
    self.setup()
  File "C:\LabPrograms\Python\Camera-ScopeFoundry\CameraMeasurement.py", line 24, in setup
    self.settings.New('record', dtype=bool, initial=False, hardware_set_func=self.setRecord, hardware_read_func=self.getRecord, reread_after_write=True)
  File "C:\ProgramData\Anaconda3\lib\site-packages\ScopeFoundry\logged_quantity.py", line 1106, in New
    lq = LoggedQuantity(name=name, dtype=dtype, **kwargs)
TypeError: __init__() got an unexpected keyword argument 'reread_after_write'

