2018-11-30T16:43:27|CRITICAL|root|Unhandled exception:Traceback (most recent call last):
  File "C:\ProgramData\Anaconda3\lib\site-packages\ScopeFoundry\hardware.py", line 208, in enable_connection
    raise err
  File "C:\ProgramData\Anaconda3\lib\site-packages\ScopeFoundry\hardware.py", line 204, in enable_connection
    self.connect()
  File "C:\LabPrograms\Python\Camera-ScopeFoundry\CameraHardware.py", line 141, in connect
    self.read_from_hardware() #read from hardware at connection
  File "C:\ProgramData\Anaconda3\lib\site-packages\ScopeFoundry\hardware.py", line 181, in read_from_hardware
    lq.read_from_hardware()
  File "C:\ProgramData\Anaconda3\lib\site-packages\ScopeFoundry\logged_quantity.py", line 161, in read_from_hardware
    val = self.hardware_read_func()
  File "C:\LabPrograms\Python\Camera-ScopeFoundry\CameraDevice.py", line 648, in getTemperature
    if self.camera_model.val ==  "C11440-22CU":
AttributeError: 'str' object has no attribute 'val'

