2018-11-08T17:34:32|CRITICAL|root|Unhandled exception:Traceback (most recent call last):
  File "C:\Users\Admin\Desktop\Camera-ScopeFoundry\CameraApp.py", line 24, in <module>
    app = HamamatsuApp(sys.argv)
  File "C:\ProgramData\Anaconda3\lib\site-packages\ScopeFoundry\base_app.py", line 332, in __init__
    self.setup()
  File "C:\Users\Admin\Desktop\Camera-ScopeFoundry\CameraApp.py", line 15, in setup
    self.add_measurement(HamamatsuMeasurement(self))
  File "C:\ProgramData\Anaconda3\lib\site-packages\ScopeFoundry\measurement.py", line 93, in __init__
    self.setup()
  File "C:\Users\Admin\Desktop\Camera-ScopeFoundry\CameraMeasurement.py", line 26, in setup
    self.imv.setImage(self.np_init)
AttributeError: 'HamamatsuMeasurement' object has no attribute 'imv'

